Workbook

Sheet Dashboard & Metrics
A1: WORK TRACKER PRO (TRACKERKERJA) v3.7 - QA E2E TEST TRACKING DASHBOARD
A4: Nama Aplikasi | B4: Work Tracker Pro (TrackerKerja) | G4: Target Platform | H4: Web ASP.NET Core 8.0 & Docker Container
A5: Versi Sistem | B5: v3.7 Enterprise Edition | G5: Basis Data | H5: SQLite Engine (EF Core 8.0)
A6: QA Lead / PIC | B6: QA Engineering Team | G6: Terakhir Diperbarui | H6: Oktober 2026
A7: Cakupan Uji | B7: 19 Modul (Web MVC, REST API, ClosedXML, Docker) | G7: Metodologi | H7: Manual UI, Postman API & E2E Flow
A9: TOTAL TEST CASES | C9: PASSED | E9: FAILED | G9: IN PROGRESS | I9: BLOCKED | J9: COMPLETION % | K9: PASS RATE %
A10: =COUNTA('E2E Test Cases Master'!A4:A150) | C10: =COUNTIF('E2E Test Cases Master'!I4:I150, "Passed") | E10: =COUNTIF('E2E Test Cases Master'!I4:I150, "Failed") | G10: =COUNTIF('E2E Test Cases Master'!I4:I150, "In Progress") | I10: =COUNTIF('E2E Test Cases Master'!I4:I150, "Blocked") | J10: =IF(A10>0, (C10+E10+I10)/A10, 0) | K10: =IF((C10+E10)>0, C10/(C10+E10), 0)
A13: RINGKASAN STATUS PENGUJIAN PER MODUL APLIKASI
A14: No | B14: Modul Aplikasi | C14: Total TC | D14: Passed | E14: Failed | F14: In Progress | G14: Blocked | H14: Ready / Draft | I14: Progress % | J14: Pass Rate % | K14: QA PIC
A15: 1 | B15: Autentikasi & Akun | C15: =COUNTIF('E2E Test Cases Master'!B$4:B$150, "Autentikasi & Akun") | D15: =COUNTIFS('E2E Test Cases Master'!B$4:B$150, "Autentikasi & Akun", 'E2E Test Cases Master'!I$4:I$150, "Passed") | E15: =COUNTIFS('E2E Test Cases Master'!B$4:B$150, "Autentikasi & Akun", 'E2E Test Cases Master'!I$4:I$150, "Failed") | F15: =COUNTIFS('E2E Test Cases Master'!B$4:B$150, "Autentikasi & Akun", 'E2E Test Cases Master'!I$4:I$150, "In Progress") | G15: =COUNTIFS('E2E Test Cases Master'!B$4:B$150, "Autentikasi & Akun", 'E2E Test Cases Master'!I$4:I$150, "Blocked") | H15: =COUNTIFS('E2E Test Cases Master'!B$4:B$150, "Autentikasi & Akun", 'E2E Test Cases Master'!I$4:I$150, "Ready") + COUNTIFS('E2E Test Cases Master'!B$4:B$150, "Autentikasi & Akun", 'E2E Test Cases Master'!I$4:I$150, "Draft") | I15: =IF(C15>0, (D15+E15+G15)/C15, 0) | J15: =IF((D15+E15)>0, D15/(D15+E15), 0) | K15: QA Engineer A
A16: 2 | B16: Multi-Company & Isolation | C16: =COUNTIF('E2E Test Cases Master'!B$4:B$150, "Multi-Company & Isolation") | D16: =COUNTIFS('E2E Test Cases Master'!B$4:B$150, "Multi-Company & Isolation", 'E2E Test Cases Master'!I$4:I$150, "Passed") | E16: =COUNTIFS('E2E Test Cases Master'!B$4:B$150, "Multi-Company & Isolation", 'E2E Test Cases Master'!I$4:I$150, "Failed") | F16: =COUNTIFS('E2E Test Cases Master'!B$4:B$150, "Multi-Company & Isolation", 'E2E Test Cases Master'!I$4:I$150, "In Progress") | G16: =COUNTIFS('E2E Test Cases Master'!B$4:B$150, "Multi-Company & Isolation", 'E2E Test Cases Master'!I$4:I$150, "Blocked") | H16: =COUNTIFS('E2E Test Cases Master'!B$4:B$150, "Multi-Company & Isolation", 'E2E Test Cases Master'!I$4:I$150, "Ready") + COUNTIFS('E2E Test Cases Master'!B$4:B$150, "Multi-Company & Isolation", 'E2E Test Cases Master'!I$4:I$150, "Draft") | I16: =IF(C16>0, (D16+E16+G16)/C16, 0) | J16: =IF((D16+E16)>0, D16/(D16+E16), 0) | K16: QA Engineer A
A17: 3 | B17: Manajemen Proyek & Kategori | C17: =COUNTIF('E2E Test Cases Master'!B$4:B$150, "Manajemen Proyek & Kategori") | D17: =COUNTIFS('E2E Test Cases Master'!B$4:B$150, "Manajemen Proyek & Kategori", 'E2E Test Cases Master'!I$4:I$150, "Passed") | E17: =COUNTIFS('E2E Test Cases Master'!B$4:B$150, "Manajemen Proyek & Kategori", 'E2E Test Cases Master'!I$4:I$150, "Failed") | F17: =COUNTIFS('E2E Test Cases Master'!B$4:B$150, "Manajemen Proyek & Kategori", 'E2E Test Cases Master'!I$4:I$150, "In Progress") | G17: =COUNTIFS('E2E Test Cases Master'!B$4:B$150, "Manajemen Proyek & Kategori", 'E2E Test Cases Master'!I$4:I$150, "Blocked") | H17: =COUNTIFS('E2E Test Cases Master'!B$4:B$150, "Manajemen Proyek & Kategori", 'E2E Test Cases Master'!I$4:I$150, "Ready") + COUNTIFS('E2E Test Cases Master'!B$4:B$150, "Manajemen Proyek & Kategori", 'E2E Test Cases Master'!I$4:I$150, "Draft") | I17: =IF(C17>0, (D17+E17+G17)/C17, 0) | J17: =IF((D17+E17)>0, D17/(D17+E17), 0) | K17: QA Engineer B
A18: 4 | B18: Manajemen Tugas & Parenting | C18: =COUNTIF('E2E Test Cases Master'!B$4:B$150, "Manajemen Tugas & Parenting") | D18: =COUNTIFS('E2E Test Cases Master'!B$4:B$150, "Manajemen Tugas & Parenting", 'E2E Test Cases Master'!I$4:I$150, "Passed") | E18: =COUNTIFS('E2E Test Cases Master'!B$4:B$150, "Manajemen Tugas & Parenting", 'E2E Test Cases Master'!I$4:I$150, "Failed") | F18: =COUNTIFS('E2E Test Cases Master'!B$4:B$150, "Manajemen Tugas & Parenting", 'E2E Test Cases Master'!I$4:I$150, "In Progress") | G18: =COUNTIFS('E2E Test Cases Master'!B$4:B$150, "Manajemen Tugas & Parenting", 'E2E Test Cases Master'!I$4:I$150, "Blocked") | H18: =COUNTIFS('E2E Test Cases Master'!B$4:B$150, "Manajemen Tugas & Parenting", 'E2E Test Cases Master'!I$4:I$150, "Ready") + COUNTIFS('E2E Test Cases Master'!B$4:B$150, "Manajemen Tugas & Parenting", 'E2E Test Cases Master'!I$4:I$150, "Draft") | I18: =IF(C18>0, (D18+E18+G18)/C18, 0) | J18: =IF((D18+E18)>0, D18/(D18+E18), 0) | K18: QA Engineer B
A19: 5 | B19: Kanban Board Interaktif | C19: =COUNTIF('E2E Test Cases Master'!B$4:B$150, "Kanban Board Interaktif") | D19: =COUNTIFS('E2E Test Cases Master'!B$4:B$150, "Kanban Board Interaktif", 'E2E Test Cases Master'!I$4:I$150, "Passed") | E19: =COUNTIFS('E2E Test Cases Master'!B$4:B$150, "Kanban Board Interaktif", 'E2E Test Cases Master'!I$4:I$150, "Failed") | F19: =COUNTIFS('E2E Test Cases Master'!B$4:B$150, "Kanban Board Interaktif", 'E2E Test Cases Master'!I$4:I$150, "In Progress") | G19: =COUNTIFS('E2E Test Cases Master'!B$4:B$150, "Kanban Board Interaktif", 'E2E Test Cases Master'!I$4:I$150, "Blocked") | H19: =COUNTIFS('E2E Test Cases Master'!B$4:B$150, "Kanban Board Interaktif", 'E2E Test Cases Master'!I$4:I$150, "Ready") + COUNTIFS('E2E Test Cases Master'!B$4:B$150, "Kanban Board Interaktif", 'E2E Test Cases Master'!I$4:I$150, "Draft") | I19: =IF(C19>0, (D19+E19+G19)/C19, 0) | J19: =IF((D19+E19)>0, D19/(D19+E19), 0) | K19: QA Engineer B
A20: 6 | B20: Timesheet & Multi-Timer | C20: =COUNTIF('E2E Test Cases Master'!B$4:B$150, "Timesheet & Multi-Timer") | D20: =COUNTIFS('E2E Test Cases Master'!B$4:B$150, "Timesheet & Multi-Timer", 'E2E Test Cases Master'!I$4:I$150, "Passed") | E20: =COUNTIFS('E2E Test Cases Master'!B$4:B$150, "Timesheet & Multi-Timer", 'E2E Test Cases Master'!I$4:I$150, "Failed") | F20: =COUNTIFS('E2E Test Cases Master'!B$4:B$150, "Timesheet & Multi-Timer", 'E2E Test Cases Master'!I$4:I$150, "In Progress") | G20: =COUNTIFS('E2E Test Cases Master'!B$4:B$150, "Timesheet & Multi-Timer", 'E2E Test Cases Master'!I$4:I$150, "Blocked") | H20: =COUNTIFS('E2E Test Cases Master'!B$4:B$150, "Timesheet & Multi-Timer", 'E2E Test Cases Master'!I$4:I$150, "Ready") + COUNTIFS('E2E Test Cases Master'!B$4:B$150, "Timesheet & Multi-Timer", 'E2E Test Cases Master'!I$4:I$150, "Draft") | I20: =IF(C20>0, (D20+E20+G20)/C20, 0) | J20: =IF((D20+E20)>0, D20/(D20+E20), 0) | K20: QA Engineer C
A21: 7 | B21: Presensi & Rekonsiliasi Absensi | C21: =COUNTIF('E2E Test Cases Master'!B$4:B$150, "Presensi & Rekonsiliasi Absensi") | D21: =COUNTIFS('E2E Test Cases Master'!B$4:B$150, "Presensi & Rekonsiliasi Absensi", 'E2E Test Cases Master'!I$4:I$150, "Passed") | E21: =COUNTIFS('E2E Test Cases Master'!B$4:B$150, "Presensi & Rekonsiliasi Absensi", 'E2E Test Cases Master'!I$4:I$150, "Failed") | F21: =COUNTIFS('E2E Test Cases Master'!B$4:B$150, "Presensi & Rekonsiliasi Absensi", 'E2E Test Cases Master'!I$4:I$150, "In Progress") | G21: =COUNTIFS('E2E Test Cases Master'!B$4:B$150, "Presensi & Rekonsiliasi Absensi", 'E2E Test Cases Master'!I$4:I$150, "Blocked") | H21: =COUNTIFS('E2E Test Cases Master'!B$4:B$150, "Presensi & Rekonsiliasi Absensi", 'E2E Test Cases Master'!I$4:I$150, "Ready") + COUNTIFS('E2E Test Cases Master'!B$4:B$150, "Presensi & Rekonsiliasi Absensi", 'E2E Test Cases Master'!I$4:I$150, "Draft") | I21: =IF(C21>0, (D21+E21+G21)/C21, 0) | J21: =IF((D21+E21)>0, D21/(D21+E21), 0) | K21: QA Engineer C
A22: 8 | B22: Catatan & Upload File Terisolasi | C22: =COUNTIF('E2E Test Cases Master'!B$4:B$150, "Catatan & Upload File Terisolasi") | D22: =COUNTIFS('E2E Test Cases Master'!B$4:B$150, "Catatan & Upload File Terisolasi", 'E2E Test Cases Master'!I$4:I$150, "Passed") | E22: =COUNTIFS('E2E Test Cases Master'!B$4:B$150, "Catatan & Upload File Terisolasi", 'E2E Test Cases Master'!I$4:I$150, "Failed") | F22: =COUNTIFS('E2E Test Cases Master'!B$4:B$150, "Catatan & Upload File Terisolasi", 'E2E Test Cases Master'!I$4:I$150, "In Progress") | G22: =COUNTIFS('E2E Test Cases Master'!B$4:B$150, "Catatan & Upload File Terisolasi", 'E2E Test Cases Master'!I$4:I$150, "Blocked") | H22: =COUNTIFS('E2E Test Cases Master'!B$4:B$150, "Catatan & Upload File Terisolasi", 'E2E Test Cases Master'!I$4:I$150, "Ready") + COUNTIFS('E2E Test Cases Master'!B$4:B$150, "Catatan & Upload File Terisolasi", 'E2E Test Cases Master'!I$4:I$150, "Draft") | I22: =IF(C22>0, (D22+E22+G22)/C22, 0) | J22: =IF((D22+E22)>0, D22/(D22+E22), 0) | K22: QA Engineer C
A23: 9 | B23: Import & Export Excel (Standard & ARMS) | C23: =COUNTIF('E2E Test Cases Master'!B$4:B$150, "Import & Export Excel (Standard & ARMS)") | D23: =COUNTIFS('E2E Test Cases Master'!B$4:B$150, "Import & Export Excel (Standard & ARMS)", 'E2E Test Cases Master'!I$4:I$150, "Passed") | E23: =COUNTIFS('E2E Test Cases Master'!B$4:B$150, "Import & Export Excel (Standard & ARMS)", 'E2E Test Cases Master'!I$4:I$150, "Failed") | F23: =COUNTIFS('E2E Test Cases Master'!B$4:B$150, "Import & Export Excel (Standard & ARMS)", 'E2E Test Cases Master'!I$4:I$150, "In Progress") | G23: =COUNTIFS('E2E Test Cases Master'!B$4:B$150, "Import & Export Excel (Standard & ARMS)", 'E2E Test Cases Master'!I$4:I$150, "Blocked") | H23: =COUNTIFS('E2E Test Cases Master'!B$4:B$150, "Import & Export Excel (Standard & ARMS)", 'E2E Test Cases Master'!I$4:I$150, "Ready") + COUNTIFS('E2E Test Cases Master'!B$4:B$150, "Import & Export Excel (Standard & ARMS)", 'E2E Test Cases Master'!I$4:I$150, "Draft") | I23: =IF(C23>0, (D23+E23+G23)/C23, 0) | J23: =IF((D23+E23)>0, D23/(D23+E23), 0) | K23: QA Engineer D
A24: 10 | B24: Anggota Tim & Profil Direktori | C24: =COUNTIF('E2E Test Cases Master'!B$4:B$150, "Anggota Tim & Profil Direktori") | D24: =COUNTIFS('E2E Test Cases Master'!B$4:B$150, "Anggota Tim & Profil Direktori", 'E2E Test Cases Master'!I$4:I$150, "Passed") | E24: =COUNTIFS('E2E Test Cases Master'!B$4:B$150, "Anggota Tim & Profil Direktori", 'E2E Test Cases Master'!I$4:I$150, "Failed") | F24: =COUNTIFS('E2E Test Cases Master'!B$4:B$150, "Anggota Tim & Profil Direktori", 'E2E Test Cases Master'!I$4:I$150, "In Progress") | G24: =COUNTIFS('E2E Test Cases Master'!B$4:B$150, "Anggota Tim & Profil Direktori", 'E2E Test Cases Master'!I$4:I$150, "Blocked") | H24: =COUNTIFS('E2E Test Cases Master'!B$4:B$150, "Anggota Tim & Profil Direktori", 'E2E Test Cases Master'!I$4:I$150, "Ready") + COUNTIFS('E2E Test Cases Master'!B$4:B$150, "Anggota Tim & Profil Direktori", 'E2E Test Cases Master'!I$4:I$150, "Draft") | I24: =IF(C24>0, (D24+E24+G24)/C24, 0) | J24: =IF((D24+E24)>0, D24/(D24+E24), 0) | K24: QA Engineer D
A25: 11 | B25: Kalender Tugas Interaktif | C25: =COUNTIF('E2E Test Cases Master'!B$4:B$150, "Kalender Tugas Interaktif") | D25: =COUNTIFS('E2E Test Cases Master'!B$4:B$150, "Kalender Tugas Interaktif", 'E2E Test Cases Master'!I$4:I$150, "Passed") | E25: =COUNTIFS('E2E Test Cases Master'!B$4:B$150, "Kalender Tugas Interaktif", 'E2E Test Cases Master'!I$4:I$150, "Failed") | F25: =COUNTIFS('E2E Test Cases Master'!B$4:B$150, "Kalender Tugas Interaktif", 'E2E Test Cases Master'!I$4:I$150, "In Progress") | G25: =COUNTIFS('E2E Test Cases Master'!B$4:B$150, "Kalender Tugas Interaktif", 'E2E Test Cases Master'!I$4:I$150, "Blocked") | H25: =COUNTIFS('E2E Test Cases Master'!B$4:B$150, "Kalender Tugas Interaktif", 'E2E Test Cases Master'!I$4:I$150, "Ready") + COUNTIFS('E2E Test Cases Master'!B$4:B$150, "Kalender Tugas Interaktif", 'E2E Test Cases Master'!I$4:I$150, "Draft") | I25: =IF(C25>0, (D25+E25+G25)/C25, 0) | J25: =IF((D25+E25)>0, D25/(D25+E25), 0) | K25: QA Engineer B
A26: 12 | B26: Developer Tools (SQL & JSON) | C26: =COUNTIF('E2E Test Cases Master'!B$4:B$150, "Developer Tools (SQL & JSON)") | D26: =COUNTIFS('E2E Test Cases Master'!B$4:B$150, "Developer Tools (SQL & JSON)", 'E2E Test Cases Master'!I$4:I$150, "Passed") | E26: =COUNTIFS('E2E Test Cases Master'!B$4:B$150, "Developer Tools (SQL & JSON)", 'E2E Test Cases Master'!I$4:I$150, "Failed") | F26: =COUNTIFS('E2E Test Cases Master'!B$4:B$150, "Developer Tools (SQL & JSON)", 'E2E Test Cases Master'!I$4:I$150, "In Progress") | G26: =COUNTIFS('E2E Test Cases Master'!B$4:B$150, "Developer Tools (SQL & JSON)", 'E2E Test Cases Master'!I$4:I$150, "Blocked") | H26: =COUNTIFS('E2E Test Cases Master'!B$4:B$150, "Developer Tools (SQL & JSON)", 'E2E Test Cases Master'!I$4:I$150, "Ready") + COUNTIFS('E2E Test Cases Master'!B$4:B$150, "Developer Tools (SQL & JSON)", 'E2E Test Cases Master'!I$4:I$150, "Draft") | I26: =IF(C26>0, (D26+E26+G26)/C26, 0) | J26: =IF((D26+E26)>0, D26/(D26+E26), 0) | K26: QA Specialist E
A27: 13 | B27: Audit Trail & Activity Log | C27: =COUNTIF('E2E Test Cases Master'!B$4:B$150, "Audit Trail & Activity Log") | D27: =COUNTIFS('E2E Test Cases Master'!B$4:B$150, "Audit Trail & Activity Log", 'E2E Test Cases Master'!I$4:I$150, "Passed") | E27: =COUNTIFS('E2E Test Cases Master'!B$4:B$150, "Audit Trail & Activity Log", 'E2E Test Cases Master'!I$4:I$150, "Failed") | F27: =COUNTIFS('E2E Test Cases Master'!B$4:B$150, "Audit Trail & Activity Log", 'E2E Test Cases Master'!I$4:I$150, "In Progress") | G27: =COUNTIFS('E2E Test Cases Master'!B$4:B$150, "Audit Trail & Activity Log", 'E2E Test Cases Master'!I$4:I$150, "Blocked") | H27: =COUNTIFS('E2E Test Cases Master'!B$4:B$150, "Audit Trail & Activity Log", 'E2E Test Cases Master'!I$4:I$150, "Ready") + COUNTIFS('E2E Test Cases Master'!B$4:B$150, "Audit Trail & Activity Log", 'E2E Test Cases Master'!I$4:I$150, "Draft") | I27: =IF(C27>0, (D27+E27+G27)/C27, 0) | J27: =IF((D27+E27)>0, D27/(D27+E27), 0) | K27: QA Specialist E
A28: 14 | B28: Master Data (Priority, Status, Milestone) | C28: =COUNTIF('E2E Test Cases Master'!B$4:B$150, "Master Data (Priority, Status, Milestone)") | D28: =COUNTIFS('E2E Test Cases Master'!B$4:B$150, "Master Data (Priority, Status, Milestone)", 'E2E Test Cases Master'!I$4:I$150, "Passed") | E28: =COUNTIFS('E2E Test Cases Master'!B$4:B$150, "Master Data (Priority, Status, Milestone)", 'E2E Test Cases Master'!I$4:I$150, "Failed") | F28: =COUNTIFS('E2E Test Cases Master'!B$4:B$150, "Master Data (Priority, Status, Milestone)", 'E2E Test Cases Master'!I$4:I$150, "In Progress") | G28: =COUNTIFS('E2E Test Cases Master'!B$4:B$150, "Master Data (Priority, Status, Milestone)", 'E2E Test Cases Master'!I$4:I$150, "Blocked") | H28: =COUNTIFS('E2E Test Cases Master'!B$4:B$150, "Master Data (Priority, Status, Milestone)", 'E2E Test Cases Master'!I$4:I$150, "Ready") + COUNTIFS('E2E Test Cases Master'!B$4:B$150, "Master Data (Priority, Status, Milestone)", 'E2E Test Cases Master'!I$4:I$150, "Draft") | I28: =IF(C28>0, (D28+E28+G28)/C28, 0) | J28: =IF((D28+E28)>0, D28/(D28+E28), 0) | K28: QA Engineer D
A29: 15 | B29: Gamifikasi & Check-In Streak | C29: =COUNTIF('E2E Test Cases Master'!B$4:B$150, "Gamifikasi & Check-In Streak") | D29: =COUNTIFS('E2E Test Cases Master'!B$4:B$150, "Gamifikasi & Check-In Streak", 'E2E Test Cases Master'!I$4:I$150, "Passed") | E29: =COUNTIFS('E2E Test Cases Master'!B$4:B$150, "Gamifikasi & Check-In Streak", 'E2E Test Cases Master'!I$4:I$150, "Failed") | F29: =COUNTIFS('E2E Test Cases Master'!B$4:B$150, "Gamifikasi & Check-In Streak", 'E2E Test Cases Master'!I$4:I$150, "In Progress") | G29: =COUNTIFS('E2E Test Cases Master'!B$4:B$150, "Gamifikasi & Check-In Streak", 'E2E Test Cases Master'!I$4:I$150, "Blocked") | H29: =COUNTIFS('E2E Test Cases Master'!B$4:B$150, "Gamifikasi & Check-In Streak", 'E2E Test Cases Master'!I$4:I$150, "Ready") + COUNTIFS('E2E Test Cases Master'!B$4:B$150, "Gamifikasi & Check-In Streak", 'E2E Test Cases Master'!I$4:I$150, "Draft") | I29: =IF(C29>0, (D29+E29+G29)/C29, 0) | J29: =IF((D29+E29)>0, D29/(D29+E29), 0) | K29: QA Engineer A
A30: 16 | B30: Notifikasi & Integrasi SMTP Email | C30: =COUNTIF('E2E Test Cases Master'!B$4:B$150, "Notifikasi & Integrasi SMTP Email") | D30: =COUNTIFS('E2E Test Cases Master'!B$4:B$150, "Notifikasi & Integrasi SMTP Email", 'E2E Test Cases Master'!I$4:I$150, "Passed") | E30: =COUNTIFS('E2E Test Cases Master'!B$4:B$150, "Notifikasi & Integrasi SMTP Email", 'E2E Test Cases Master'!I$4:I$150, "Failed") | F30: =COUNTIFS('E2E Test Cases Master'!B$4:B$150, "Notifikasi & Integrasi SMTP Email", 'E2E Test Cases Master'!I$4:I$150, "In Progress") | G30: =COUNTIFS('E2E Test Cases Master'!B$4:B$150, "Notifikasi & Integrasi SMTP Email", 'E2E Test Cases Master'!I$4:I$150, "Blocked") | H30: =COUNTIFS('E2E Test Cases Master'!B$4:B$150, "Notifikasi & Integrasi SMTP Email", 'E2E Test Cases Master'!I$4:I$150, "Ready") + COUNTIFS('E2E Test Cases Master'!B$4:B$150, "Notifikasi & Integrasi SMTP Email", 'E2E Test Cases Master'!I$4:I$150, "Draft") | I30: =IF(C30>0, (D30+E30+G30)/C30, 0) | J30: =IF((D30+E30)>0, D30/(D30+E30), 0) | K30: QA Engineer D
A31: 17 | B31: Multi-Instance Node Synchronization | C31: =COUNTIF('E2E Test Cases Master'!B$4:B$150, "Multi-Instance Node Synchronization") | D31: =COUNTIFS('E2E Test Cases Master'!B$4:B$150, "Multi-Instance Node Synchronization", 'E2E Test Cases Master'!I$4:I$150, "Passed") | E31: =COUNTIFS('E2E Test Cases Master'!B$4:B$150, "Multi-Instance Node Synchronization", 'E2E Test Cases Master'!I$4:I$150, "Failed") | F31: =COUNTIFS('E2E Test Cases Master'!B$4:B$150, "Multi-Instance Node Synchronization", 'E2E Test Cases Master'!I$4:I$150, "In Progress") | G31: =COUNTIFS('E2E Test Cases Master'!B$4:B$150, "Multi-Instance Node Synchronization", 'E2E Test Cases Master'!I$4:I$150, "Blocked") | H31: =COUNTIFS('E2E Test Cases Master'!B$4:B$150, "Multi-Instance Node Synchronization", 'E2E Test Cases Master'!I$4:I$150, "Ready") + COUNTIFS('E2E Test Cases Master'!B$4:B$150, "Multi-Instance Node Synchronization", 'E2E Test Cases Master'!I$4:I$150, "Draft") | I31: =IF(C31>0, (D31+E31+G31)/C31, 0) | J31: =IF((D31+E31)>0, D31/(D31+E31), 0) | K31: QA Specialist E
A32: 18 | B32: Tema Tampilan (40 Tema) & Font Engine | C32: =COUNTIF('E2E Test Cases Master'!B$4:B$150, "Tema Tampilan (40 Tema) & Font Engine") | D32: =COUNTIFS('E2E Test Cases Master'!B$4:B$150, "Tema Tampilan (40 Tema) & Font Engine", 'E2E Test Cases Master'!I$4:I$150, "Passed") | E32: =COUNTIFS('E2E Test Cases Master'!B$4:B$150, "Tema Tampilan (40 Tema) & Font Engine", 'E2E Test Cases Master'!I$4:I$150, "Failed") | F32: =COUNTIFS('E2E Test Cases Master'!B$4:B$150, "Tema Tampilan (40 Tema) & Font Engine", 'E2E Test Cases Master'!I$4:I$150, "In Progress") | G32: =COUNTIFS('E2E Test Cases Master'!B$4:B$150, "Tema Tampilan (40 Tema) & Font Engine", 'E2E Test Cases Master'!I$4:I$150, "Blocked") | H32: =COUNTIFS('E2E Test Cases Master'!B$4:B$150, "Tema Tampilan (40 Tema) & Font Engine", 'E2E Test Cases Master'!I$4:I$150, "Ready") + COUNTIFS('E2E Test Cases Master'!B$4:B$150, "Tema Tampilan (40 Tema) & Font Engine", 'E2E Test Cases Master'!I$4:I$150, "Draft") | I32: =IF(C32>0, (D32+E32+G32)/C32, 0) | J32: =IF((D32+E32)>0, D32/(D32+E32), 0) | K32: QA Engineer A
A33: 19 | B33: RESTful API & Swagger Bearer Auth | C33: =COUNTIF('E2E Test Cases Master'!B$4:B$150, "RESTful API & Swagger Bearer Auth") | D33: =COUNTIFS('E2E Test Cases Master'!B$4:B$150, "RESTful API & Swagger Bearer Auth", 'E2E Test Cases Master'!I$4:I$150, "Passed") | E33: =COUNTIFS('E2E Test Cases Master'!B$4:B$150, "RESTful API & Swagger Bearer Auth", 'E2E Test Cases Master'!I$4:I$150, "Failed") | F33: =COUNTIFS('E2E Test Cases Master'!B$4:B$150, "RESTful API & Swagger Bearer Auth", 'E2E Test Cases Master'!I$4:I$150, "In Progress") | G33: =COUNTIFS('E2E Test Cases Master'!B$4:B$150, "RESTful API & Swagger Bearer Auth", 'E2E Test Cases Master'!I$4:I$150, "Blocked") | H33: =COUNTIFS('E2E Test Cases Master'!B$4:B$150, "RESTful API & Swagger Bearer Auth", 'E2E Test Cases Master'!I$4:I$150, "Ready") + COUNTIFS('E2E Test Cases Master'!B$4:B$150, "RESTful API & Swagger Bearer Auth", 'E2E Test Cases Master'!I$4:I$150, "Draft") | I33: =IF(C33>0, (D33+E33+G33)/C33, 0) | J33: =IF((D33+E33)>0, D33/(D33+E33), 0) | K33: QA Specialist E
B34: TOTAL KESELURUHAN | C34: =SUM(C15:C33) | D34: =SUM(D15:D33) | E34: =SUM(E15:E33) | F34: =SUM(F15:F33) | G34: =SUM(G15:G33) | H34: =SUM(H15:H33) | I34: =IF(C34>0, (D34+E34+G34)/C34, 0) | J34: =IF((D34+E34)>0, D34/(D34+E34), 0)

Sheet E2E Test Cases Master
A1: MASTER REPOSITORY TEST CASE END-TO-END - WORK TRACKER PRO v3.7
A3: TC ID | B3: Modul Utama | C3: Sub-Fitur / Komponen | D3: Tipe Pengujian | E3: Skenario Pengujian | F3: Prasyarat (Preconditions) | G3: Langkah-Langkah Pengujian | H3: Data Pengujian | I3: Status | J3: Prioritas | K3: Hasil yang Diharapkan | L3: Hasil Aktual | M3: Tipe Eksekusi | N3: Tester | O3: Tgl Eksekusi | P3: Defect ID | Q3: Catatan / Bukti
A4: TC-AUTH-001 | B4: Autentikasi & Akun | C4: Registrasi Akun Baru | D4: E2E Flow | E4: Pendaftaran pengguna baru dengan data valid menghasilkan status pending approval | F4: Aplikasi aktif, halaman /Account/Register dapat diakses | G4: 1. Buka /Account/Register 2. Isi Username, Email, Password, Corporate Code, Full Name 3. Klik Daftar | H4: Username: john_qa, Email: john@company.com, Pass: Pass@1234, Code: CORP01 | I4: Passed | J4: Critical | K4: Akun tersimpan di DB dengan IsApproved=0, diarahkan ke info Menunggu Persetujuan Admin | L4: Sesuai, muncul alert menunggu approval | M4: Manual UI | N4: QA Engineer A | O4: 2026-10-01 | Q4: Verified
A5: TC-AUTH-002 | B5: Autentikasi & Akun | C5: Login Akun Belum Diapprove | D5: Negative / Security | E5: Pengguna yang belum disetujui tidak dapat login ke sistem | F5: Akun john_qa sudah terdaftar dengan IsApproved=0 | G5: 1. Buka /Account/Login 2. Masukkan username john_qa & password 3. Klik tombol Masuk | H5: Username: john_qa, Pass: Pass@1234 | I5: Passed | J5: High | K5: Login gagal, muncul pesan: 'Akun Anda sedang menunggu persetujuan Administrator.' | L5: Sesuai, dicegah masuk | M5: Manual UI | N5: QA Engineer A | O5: 2026-10-01 | Q5: Verified
A6: TC-AUTH-003 | B6: Autentikasi & Akun | C6: Admin Approval Workflow | D6: E2E Flow | E6: Administrator menyetujui akun baru melalui menu Approval | F6: Login sebagai Admin; ada akun pending approval | G6: 1. Buka menu Admin > User Approval 2. Temukan user john_qa 3. Klik tombol Setujui (Approve) 4. Konfirmasi dialog | H6: User ID target: john_qa | I6: Passed | J6: Critical | K6: Status user berubah menjadi IsApproved=1, user john_qa kini dapat login sukses | L6: User berhasil di-approve dan login lancar | M6: Manual UI | N6: QA Engineer A | O6: 2026-10-01 | Q6: Verified
A7: TC-AUTH-004 | B7: Autentikasi & Akun | C7: Dual Auth (Cookie & JWT API) | D7: Integration / Security | E7: Login web menghasilkan Cookie Auth, dan login API menghasilkan Bearer JWT yang valid | F7: Endpoint /api/auth/login dan web login aktif | G7: 1. Login web via browser (cek Cookie .AspNetCore.Cookies) 2. POST /api/auth/login via Postman (cek format JWT & claim) | H7: Creds: admin / Admin@123 | I7: Passed | J7: Critical | K7: Web login sukses dengan cookie HttpOnly; API login menghasilkan token JWT berisi claim Role & CompanyCode | L7: Keduanya berfungsi independen dan aman | M7: API Postman | N7: QA Specialist E | O7: 2026-10-02 | Q7: Verified
A8: TC-AUTH-005 | B8: Autentikasi & Akun | C8: Session Timeout & Auto Logout | D8: Security / Boundary | E8: Inaktivitas pengguna selama 1 jam memicu auto-logout otomatis | F8: User sedang login di dashboard web | G8: 1. Biarkan sesi tidak aktif atau trigger inactivity timer 3600 detik di browser console 2. Lakukan navigasi klik | H8: Session idle timeout = 3600s | I8: In Progress | J8: High | K8: session-manager.js mendeteksi timeout dan redirect otomatis ke /Account/Login?reason=timeout | L8: Script session guard aktif, verifikasi auto redirect | M8: Manual UI | N8: QA Engineer A | O8: 2026-10-03 | Q8: Ongoing test
A9: TC-AUTH-006 | B9: Autentikasi & Akun | C9: Lupa & Reset Password | D9: Functional | E9: Permintaan reset password mengirimkan token valid dan memperbarui sandi | F9: SMTP terkonfigurasi atau token reset tercatat di log | G9: 1. Buka /Account/ForgotPassword 2. Masukkan email terdaftar 3. Buka link reset dengan token 4. Masukkan password baru | H9: Email: user@company.com, New Pass: NewPass@2026 | I9: Ready | J9: High | K9: Password lama tidak berlaku, login berhasil dengan password baru | M9: Manual UI | N9: QA Engineer A | Q9: Siap diuji
A10: TC-COMP-001 | B10: Multi-Company & Isolation | C10: Corporate Code Data Isolation | D10: Security / E2E | E10: User Company A dilarang melihat data tugas, proyek, dan anggota Company B | F10: Dua akun: User_A (Company ALPHA) dan User_B (Company BETA) | G10: 1. Login User_A, buat proyek 'Project Alpha' & tugas 'Task Alpha' 2. Logout, Login User_B 3. Buka halaman Project, Task, Member | H10: Corp A: ALPHA, Corp B: BETA | I10: Passed | J10: Critical | K10: Data milik ALPHA sama sekali tidak muncul di daftar milik BETA (Query filter CompanyCode aktif) | L10: Isolasi data 100% aman, tidak bocor | M10: Manual UI | N10: QA Engineer A | O10: 2026-10-02 | Q10: Verified
A11: TC-COMP-002 | B11: Multi-Company & Isolation | C11: SuperAdmin Grouping View | D11: Functional | E11: SuperAdmin dapat melihat seluruh perusahaan dan melakukan filter per Corporate Code | F11: Login sebagai SuperAdmin | G11: 1. Buka Dashboard atau Member List 2. Gunakan dropdown filter Corporate Code 3. Pilih 'Semua' lalu pilih spesifik perusahaan | H11: Filter: ALL vs CORP01 vs CORP02 | I11: Passed | J11: Medium | K11: Daftar tersaring secara dinamis sesuai pilihan kode perusahaan tanpa bug tampilan | L11: Filter berfungsi tepat | M11: Manual UI | N11: QA Engineer A | O11: 2026-10-02 | Q11: Verified
A12: TC-PROJ-001 | B12: Manajemen Proyek & Kategori | C12: Create Project Baru | D12: Functional | E12: Pembuatan proyek baru dengan nama, anggaran (budget), tenggat waktu, dan kategori | F12: Role Manager / Admin | G12: 1. Buka menu Projects > Tambah Proyek 2. Isi Nama, Deskripsi, Kategori, Budget, Start Date, End Date 3. Simpan | H12: Nama: Sistem Billing v2, Budget: 50.000.000, Target: 2026-12-31 | I12: Passed | J12: High | K12: Proyek tersimpan di SQLite, muncul di list dengan badge status 'Planning/Active' | L12: Tersimpan sukses, budget terformat rupiah | M12: Manual UI | N12: QA Engineer B | O12: 2026-10-03 | Q12: Verified
A13: TC-PROJ-002 | B13: Manajemen Proyek & Kategori | C13: Update Status & Progress Proyek | D13: Functional | E13: Perubahan status proyek dari Planning ke Active ke Completed | F13: Proyek 'Sistem Billing v2' sudah ada | G13: 1. Klik Edit Proyek 2. Ubah status ke Active 3. Tambah beberapa task selesai 4. Cek progress bar proyek | H13: Status: Active, Task Done: 3 dari 5 | I13: Passed | J13: Medium | K13: Persentase progress proyek terkalkulasi otomatis berdasarkan rasio task selesai | L13: Kalkulasi persentase akurat 60% | M13: Manual UI | N13: QA Engineer B | O13: 2026-10-03 | Q13: Verified
A14: TC-PROJ-003 | B14: Manajemen Proyek & Kategori | C14: Restriksi Akses Role Member Biasa | D14: Security / RBAC | E14: Role Member dilarang menghapus atau mengubah anggaran proyek penting | F14: Login sebagai role Member biasa | G14: 1. Buka halaman Project Detail 2. Coba akses tombol Edit / Hapus via UI dan direct URL /Project/Delete/1 | H14: User role: Member | I14: Passed | J14: High | K14: Tombol hapus tidak muncul; request direct URL diblokir dengan HTTP 403 / Redirect Access Denied | L14: RBAC proteksi aktif | M14: Manual UI | N14: QA Engineer B | O14: 2026-10-03 | Q14: Verified
A15: TC-TASK-001 | B15: Manajemen Tugas & Parenting | C15: Create Parent Task Lengkap | D15: E2E Flow | E15: Pembuatan tugas induk dengan estimasi jam, prioritas, status, deadline, milestone | F15: Login sebagai User / Manager | G15: 1. Buka menu Tasks > Buat Tugas Baru 2. Isi Judul, Deskripsi, Estimasi 16 Jam, Prioritas Tinggi, Milestone Sprint 1 3. Simpan | H15: Judul: Integrasi Gateway Pembayaran, Est: 16 jam, Priority: High | I15: Passed | J15: Critical | K15: Tugas tersimpan, muncul di daftar tugas dengan ID unik dan badge milestone | L15: Tersimpan dengan baik | M15: Manual UI | N15: QA Engineer B | O15: 2026-10-04 | Q15: Verified
A16: TC-TASK-002 | B16: Manajemen Tugas & Parenting | C16: Hierarki Subtask (Parent-Child) | D16: Functional | E16: Pembuatan Subtask di bawah Parent Task dan auto-kalkulasi agregat progress | F16: Parent Task ID #10 sudah aktif | G16: 1. Buka detail Parent Task #10 2. Klik Tambah Subtask 3. Buat Subtask A (4 Jam) & Subtask B (4 Jam) 4. Tandai Subtask A 'Done' | H16: Parent ID: 10, Subtask 1: Selesai, Subtask 2: Pending | I16: Passed | J16: High | K16: Subtask terhubung ke ParentId=10, progress Parent task otomatis naik ke 50% | L16: Agregasi progress subtask berjalan mulus | M16: Manual UI | N16: QA Engineer B | O16: 2026-10-04 | Q16: Verified
A17: TC-TASK-003 | B17: Manajemen Tugas & Parenting | C17: Pencatatan Obstacle & Solution | D17: Functional | E17: Pencatatan kendala teknis (Obstacle) dan solusi penanganan pada task | F17: Task sedang berstatus 'In Progress' | G17: 1. Buka modal edit / detail task 2. Tulis kendala pada field Kendala (Obstacle) 3. Tulis solusi pada field Solusi (Solution) 4. Simpan | H17: Obstacle: API Vendor timeout, Solution: Tambah timeout retry 3x | I17: Passed | J17: Medium | K17: Field tersimpan, badge warning kendala muncul di kartu list tugas | L17: Tercatat di DB dan tampil di view | M17: Manual UI | N17: QA Engineer B | O17: 2026-10-04 | Q17: Verified
A18: TC-TASK-004 | B18: Manajemen Tugas & Parenting | C18: Unified Task Save (Task + Timesheet) | D18: E2E Flow | E18: Menyimpan pembaruan status tugas sekaligus mencatat jam kerja timesheet dalam 1 form | F18: Task sedang dikerjakan | G18: 1. Buka halaman Edit Task 2. Update status ke 'Done' 3. Isi input jam kerja manual 2.5 jam di bagian Timesheet terintegrasi 4. Simpan | H18: Task Status: Done, Hours: 2.5 jam, Note: Fix unit test | I18: Passed | J18: High | K18: Perubahan task tersimpan dan row baru di tabel Timesheets otomatis terbuat tanpa error | L18: Berhasil terintegrasi (Unified Save OK) | M18: Manual UI | N18: QA Engineer B | O18: 2026-10-04 | Q18: Verified
A19: TC-TASK-005 | B19: Manajemen Tugas & Parenting | C19: Filter & Pencarian Lanjutan Tugas | D19: UI / Functional | E19: Memfilter tugas berdasarkan kombinasi Project, Assignee, Prioritas, Status, dan Rentang Waktu | F19: Ada minimal 20 task bervariasi di database | G19: 1. Di halaman Tasks Index, gunakan dropdown filter 2. Filter Status='In Progress' dan Priority='High' 3. Cek hasil tabel AJAX | H19: Filter kombinasi multi-kriteria | I19: Passed | J19: Medium | K19: Tabel melakukan reload data via AJAX tanpa refresh halaman penuh (Zero reload), data sesuai filter | L19: ajax-grid-manager.js bekerja responsif | M19: Manual UI | N19: QA Engineer B | O19: 2026-10-04 | Q19: Verified
A20: TC-KANB-001 | B20: Kanban Board Interaktif | C20: Drag-and-Drop Kartu Antar Kolom | D20: UI / Interactive | E20: Memindahkan kartu tugas antar kolom status (Backlog -> To Do -> In Progress -> Review -> Done) | F20: Halaman /Task/Kanban terbuka | G20: 1. Klik dan tahan kartu tugas di kolom 'To Do' 2. Seret (drag) ke kolom 'In Progress' 3. Lepas mouse (drop) | H20: Task ID #15, Kolom target: In Progress | I20: Passed | J20: Critical | K20: Kartu berpindah posisi, request AJAX update status dikirim di background, toast notifikasi sukses muncul | L20: SortableJS drag-and-drop mulus | M20: Manual UI | N20: QA Engineer B | O20: 2026-10-05 | Q20: Verified
A21: TC-KANB-002 | B21: Kanban Board Interaktif | C21: Optimistic UI & Revert on Failure | D21: Resilience / Boundary | E21: Jika request update AJAX gagal (misal koneksi terputus), posisi kartu kembali ke kolom awal | F21: Matikan koneksi / simulasi HTTP 500 | G21: 1. Drag kartu ke kolom lain saat offline / network throttling Offline 2. Lepaskan kartu | H21: Status network: Offline | I21: In Progress | J21: High | K21: Muncul error toast, dan kartu otomatis dikembalikan ke posisi asal (rollback) | L21: Sedang diuji skenario network error | M21: Manual UI | N21: QA Engineer B | O21: 2026-10-05 | Q21: Ongoing test
... A28: TC-ATTD-002 | B28: Presensi & Rekonsiliasi Absensi | C28: Check-Out Harian & Kalkulasi Jam Kerja | D28: Functional | E28: Pengguna melakukan check-out harian dan sistem mengkalkulasi durasi kerja efektif | F28: Pengguna sudah check-in sebelumnya | G28: 1. Buka menu Attendance 2. Klik 'Check-Out Sekarang' 3. Konfirmasi dialog | H28: Waktu check-out jam sekarang | I28: Passed | J28: Critical | K28: Check-out tersimpan, total durasi jam kerja harian otomatis terhitung dan ditampilkan | L28: Durasi kerja terhitung otomatis | M28: Manual UI | N28: QA Engineer C | O28: 2026-10-06 | Q28: Verified
A29: TC-ATTD-003 | B29: Presensi & Rekonsiliasi Absensi | C29: Pengajuan Cuti / Izin / Sakit | D29: Functional | E29: Pengguna mengajukan izin sakit/cuti dengan mengunggah surat keterangan | F29: Halaman Pengajuan Presensi | G29: 1. Klik Ajukan Ketidakhadiran 2. Pilih jenis 'Sakit' 3. Tentukan tanggal 4. Unggah foto surat dokter (.jpg) 5. Submit | H29: Jenis: Sakit, File: surat_dokter.jpg (800KB) | I29: Ready | J29: High | K29: Pengajuan tersimpan dengan status 'Menunggu Approval Manager', file terupload aman | M29: Manual UI | N29: QA Engineer C | Q29: Siap diuji
A30: TC-ATTD-004 | B30: Presensi & Rekonsiliasi Absensi | C30: Rekonsiliasi Absensi Tim oleh Manager | D30: RBAC / Workflow | E30: Manager/Admin menyetujui atau menolak permohonan izin/cuti dan koreksi presensi bawahan | F30: Login sebagai Manager; ada permohonan pending | G30: 1. Buka menu Attendance > Rekonsiliasi Tim 2. Pilih pengajuan anggota tim 3. Klik 'Approve' | H30: Request ID #5 | I30: Ready | J30: High | K30: Status permohonan berubah menjadi 'Disetujui', rekap kehadiran tim langsung ter-update | M30: Manual UI | N30: QA Engineer C | Q30: Siap diuji
A31: TC-NOTE-001 | B31: Catatan & Upload File Terisolasi | C31: Create Note dengan Quill.js Rich Text | D31: Functional | E31: Membuat catatan baru lengkap dengan formatting tebal, miring, list, dan link | F31: Halaman /Note terbuka | G31: 1. Klik Tambah Catatan 2. Masukkan Judul Catatan 3. Tulis konten menggunakan editor Quill.js 4. Simpan | H31: Judul: Spesifikasi Arsitektur v3.7, Konten: formatted HTML | I31: Passed | J31: Medium | K31: Catatan tersimpan dengan format styling utuh dan aman dari script injection (XSS sanitized) | L31: Quill editor berfungsi baik, tersimpan rapi | M31: Manual UI | N31: QA Engineer C | O31: 2026-10-06 | Q31: Verified
A32: TC-NOTE-002 | B32: Catatan & Upload File Terisolasi | C32: Multi-File Upload Terisolasi Folder User | D32: Security / File | E32: Unggah multi-file lampiran tersimpan di folder terisolasi /uploads/notes/{username}/ | F32: Catatan sedang diedit | G32: 1. Klik tombol Unggah Lampiran 2. Pilih 3 file: file1.pdf, file2.png, file3.docx 3. Klik Upload | H32: Username: john_qa, Files: 3 berkas lampiran | I32: Passed | J32: High | K32: Semua file tersimpan secara fisik di wwwroot/uploads/notes/john_qa/ tanpa tabrakan nama file (UUID/Timestamped) | L32: File terisolasi per folder username | M32: Manual UI | N32: QA Engineer C | O32: 2026-10-06 | Q32: Verified
A33: TC-NOTE-003 | B33: Catatan & Upload File Terisolasi | C33: Proteksi Path Traversal pada Download/Hapus | D33: Security | E33: Mencegah eksploitasi path traversal (../) pada akses file attachment | F33: File attachment tersimpan di sistem | G33: 1. Kirim request GET /Note/DownloadFile?path=../../appsettings.json via Postman | H33: Payload: ../../appsettings.json | I33: Passed | J33: Critical | K33: Request ditolak dengan HTTP 400 Bad Request atau 404; file sistem sensitif tidak dapat diakses | L33: Path traversal validation berfungsi kuat | M33: API Postman | N33: QA Specialist E | O33: 2026-10-06 | Q33: Verified
A34: TC-EXCL-001 | B34: Import & Export Excel (Standard & ARMS) | C34: Ekspor Excel Format Standar (9 Kolom) | D34: Functional | E34: Ekspor seluruh tugas atau berdasarkan filter periode ke format spreadsheet standar 9-kolom | F34: Data tugas tersedia di database | G34: 1. Buka menu Import/Export 2. Pilih format: Standar 9-Kolom 3. Tentukan rentang tanggal 1 bulan terakhir 4. Klik Ekspor | H34: Filter rentang: 2026-09-01 s.d. 2026-09-30 | I34: Passed | J34: High | K34: File .xlsx terunduh dengan 9 kolom standar (ID, Judul, Proyek, Status, Prioritas, Estimasi, Actual, PIC, Deadline) | L34: File valid, data lengkap | M34: Manual UI | N34: QA Engineer D | O34: 2026-10-07 | Q34: Verified
A35: TC-EXCL-002 | B35: Import & Export Excel (Standard & ARMS) | C35: Ekspor Excel Format ARMS Enterprise (21 Kolom) | D35: Functional | E35: Ekspor data ke format ARMS spesifik enterprise dengan 21 kolom komprehensif | F35: Data tugas dengan obstacle, solution, milestone tersedia | G35: 1. Buka menu Import/Export 2. Pilih format: ARMS Enterprise (21 Kolom) 3. Klik Ekspor | H35: Format: ARMS 21-kolom | I35: Passed | J35: Critical | K35: File .xlsx terunduh dengan struktur 21 kolom persis sesuai template ARMS spesifikasi | L35: 21 Kolom ter-render presisi | M35: Manual UI | N35: QA Engineer D | O35: 2026-10-07 | Q35: Verified
A36: TC-EXCL-003 | B36: Import & Export Excel (Standard & ARMS) | C36: Impor Excel ARMS dengan Validasi & Preview | D36: E2E Flow | E36: Mengunggah file Excel ARMS, sistem memvalidasi isi baris, menampilkan preview, lalu mengimpor ke DB | F36: File template ARMS terisi 10 baris tugas valid | G36: 1. Buka menu Impor Excel 2. Unggah file arms_data.xlsx 3. Klik 'Pratinjau (Preview)' 4. Periksa tabel review 5. Klik 'Konfirmasi Impor' | H36: File: arms_data.xlsx (10 rows) | I36: Passed | J36: Critical | K36: 10 tugas baru berhasil masuk ke database SQLite tanpa duplikasi dan relasi proyek terbentuk benar | L36: Import lancar, 10 baris masuk utuh | M36: Manual UI | N36: QA Engineer D | O36: 2026-10-07 | Q36: Verified
A37: TC-EXCL-004 | B37: Import & Export Excel (Standard & ARMS) | C37: Validasi Error Handling File Corrupt / Wrong Format | D37: Negative | E37: Sistem menolak file bukan Excel atau struktur sheet rusak dengan pesan ramah pengguna | F37: File berkas teks .txt yang diubah ekstensi jadi .xlsx atau sheet kosong | G37: 1. Unggah file invalid.xlsx pada form Impor 2. Klik Pratinjau | H37: File rusak / corruped | I37: Passed | J37: Medium | K37: Sistem menampilkan alert error: 'Format file tidak sesuai skema template yang didukung' tanpa crash HTTP 500 | L37: Error handling ClosedXML terjaga rapi | M37: Manual UI | N37: QA Engineer D | O37: 2026-10-07 | Q37: Verified
A38: TC-MEMB-001 | B38: Anggota Tim & Profil Direktori | C38: Pure Grid Card Direktori & Live Search | D38: UI / Interactive | E38: Menampilkan daftar rekan tim dalam layout Pure Grid Card dengan fitur live search cepat | F38: Halaman /Member terbuka | G38: 1. Buka menu Team Members 2. Ketik nama 'Alex' di kolom pencarian cepat | H38: Kata kunci: 'Alex' | I38: Passed | J38: Medium | K38: Kartu grid otomatis terfilter secara instan hanya menampilkan anggota yang cocok | L38: Pencarian instan dan grid rapi | M38: Manual UI | N38: QA Engineer D | O38: 2026-10-07 | Q38: Verified
A39: TC-MEMB-002 | B39: Anggota Tim & Profil Direktori | C39: Upload Foto Profil & Cover Banner | D39: Functional | E39: Pengguna memperbarui foto avatar dan foto cover banner pada profil pribadi | F39: Halaman /Account/Profile | G39: 1. Klik ganti Avatar (pilih avatar.png) 2. Klik ganti Cover Banner (pilih banner.jpg) 3. Simpan Profil | H39: Avatar: 200x200px, Cover: 1200x300px | I39: Passed | J39: Medium | K39: Gambar tersimpan di /uploads/avatars/ dan /uploads/covers/, tampilan profil langsung ter-update | L39: Upload gambar profil sukses | M39: Manual UI | N39: QA Engineer D | O39: 2026-10-07 | Q39: Verified
A40: TC-MEMB-003 | B40: Anggota Tim & Profil Direktori | C40: Hapus Permanen Akun (Admin & Self-Delete) | D40: Security / Data | E40: Penghapusan akun membersihkan foreign key atau menganonimkan tugas terkait tanpa merusak referensial integritas DB | F40: Akun tester dummy yang memiliki relasi tugas | G40: 1. Login Admin 2. Buka menu Member > Aksi Hapus Akun 3. Konfirmasi teks 'HAPUS' 4. Submit | H40: Target user ID: tester_dummy | I40: Passed | J40: Critical | K40: Akun terhapus, data tugas tetap terjaga (relasi diset null/anonim), tidak terjadi SQLite foreign key constraint exception | L40: Verifikasi self-delete & admin delete lolos | M40: Manual UI | N40: QA Engineer D | O40: 2026-10-07 | Q40: Verified
A41: TC-CAL-001 | B41: Kalender Tugas Interaktif | C41: Render Kalender FullCalendar dengan Event Tugas | D41: UI / Interactive | E41: Menampilkan kalender bulanan dengan badge event tugas berdasarkan tenggat waktu (deadline) | F41: Ada minimal 5 tugas dengan deadline bulan ini | G41: 1. Buka menu Calendar 2. Amati event di tanggal-tanggal tertentu 3. Klik salah satu event tugas | H41: Event bulan berjalan | I41: Passed | J41: Medium | K41: Kalender ter-render sempurna, klik event memunculkan modal detail singkat tugas beserta link ke edit | L41: FullCalendar bekerja mulus | M41: Manual UI | N41: QA Engineer B | O41: 2026-10-07 | Q41: Verified
A42: TC-CAL-002 | B42: Kalender Tugas Interaktif | C42: Role-Based Scope Filter (Pribadi vs Seluruh Tim) | D42: RBAC / Security | E42: User biasa hanya dapat melihat tugasnya sendiri, Admin dapat melihat tugas seluruh anggota tim | F42: Login User biasa vs Login Admin | G42: 1. Pada User biasa, cek toggle scope (tidak tersedia / terkunci tugas pribadi) 2. Pada Admin, aktifkan toggle 'Tampilkan Seluruh Tim' | H42: Scope: Personal vs Team | I42: Passed | J42: High | K42: User biasa hanya melihat tugas sendiri di kalender; Admin dapat melihat seluruh tugas tim dengan warna penanda per user | L42: Filter role scope bekerja tepat | M42: Manual UI | N42: QA Engineer B | O42: 2026-10-07 | Q42: Verified
... A52: TC-GAM-001 | B52: Gamifikasi & Check-In Streak | C52: Daily Check-In & Penambahan Poin Streak | D52: Gamification / E2E | E52: Check-in berturut-turut menambah hitungan streak hari dan poin gamifikasi | F52: User aktif login di sistem | G52: 1. Buka menu Gamifikasi / Check-In Harian 2. Klik tombol 'Daily Check-In Hari Ini' | H52: User: john_qa | I52: Passed | J52: Medium | K52: Poin bertambah +10, streak bertambah +1 hari, konfeti/animasi reward muncul | L52: Animasi dan poin bertambah | M52: Manual UI | N52: QA Engineer A | O52: 2026-10-08 | Q52: Verified
A53: TC-GAM-002 | B53: Gamifikasi & Check-In Streak | C53: Otomatisasi Award Master Badge Gaul | D53: Gamification | E53: Pencapaian streak tertentu otomatis membuka badge prestasi (misal: 'Streak Master 7 Hari') | F53: User mencapai streak hari ke-7 | G53: 1. Lakukan check-in hari ke-7 2. Buka tab Badges & Koleksi | H53: Streak: 7 hari berturut-turut | I53: Ready | J53: Medium | K53: Badge 'Streak Master' otomatis terbuka (Unlocked) dan tampil di profil pengguna | M53: Manual UI | N53: QA Engineer A | Q53: Siap diuji
A54: TC-GAM-003 | B54: Gamifikasi & Check-In Streak | C54: Leaderboard Tim & Penukaran Hadiah | D54: Gamification | E54: Peringkat leaderboard tim ter-update berdasarkan total poin akumulasi | F54: Beberapa anggota memiliki variasi poin | G54: 1. Buka menu Leaderboard 2. Verifikasi urutan peringkat user teratas | H54: Peringkat top 10 | I54: Ready | J54: Low | K54: Peringkat terurut menurun dari skor tertinggi ke terendah secara akurat | M54: Manual UI | N54: QA Engineer A | Q54: Siap diuji
A55: TC-NOTIF-001 | B55: Notifikasi & Integrasi SMTP Email | C55: Notifikasi In-App Saat Ditugaskan Task | D55: Functional | E55: Pengguna menerima notifikasi lonceng saat diberi tugas baru oleh rekan tim | F55: User A menugaskan task ke User B | G55: 1. User A buat task dengan Assignee = User B 2. Login User B, amati ikon lonceng navbar | H55: Assignee: User B | I55: Passed | J55: High | K55: Badge angka merah pada ikon lonceng bertambah, notifikasi tugas baru muncul saat diklik | L55: In-app notification real-time | M55: Manual UI | N55: QA Engineer D | O55: 2026-10-08 | Q55: Verified
A56: TC-NOTIF-002 | B56: Notifikasi & Integrasi SMTP Email | C56: Konfigurasi Server SMTP & Test Email | D56: Functional / Integration | E56: Pengaturan host SMTP, port, username, password, dan pengiriman uji email | F56: Login Administrator, menu Configuration > Email Settings | G56: 1. Isi SMTP Server, Port 587, User, Password, SSL=True 2. Klik 'Kirim Uji Coba Email' 3. Masukkan email penerima | H56: SMTP Host: smtp.mailtrap.io / gmail | I56: Passed | J56: High | K56: Email uji coba terkirim sukses tanpa error timeout atau sertifikat SSL | L56: Test email berhasil masuk ke inbox/trap | M56: Manual UI | N56: QA Engineer D | O56: 2026-10-08 | Q56: Verified
...

Sheet Execution Cycles
A1: SIKLUS PENGUJIAN & RELEASE RUN TRACKER - WORK TRACKER PRO v3.7
A4: Siklus Uji (Cycle ID) | B4: Nama Siklus Pengujian | C4: Tujuan & Lingkup Pengujian | D4: Tgl Mulai | E4: Tgl Selesai | F4: Total TC | G4: Passed | H4: Failed | I4: Pass Rate | J4: Status Siklus
A5: CYCLE-01 | B5: Smoke / Sanity Test v3.7 | C5: Verifikasi jalur kritis login, dashboard, buat tugas, check-in | D5: 2026-10-01 | E5: 2026-10-02 | F5: 15 | G5: 15 | H5: 0 | I5: =G5/F5 | J5: Completed (Passed)
A6: CYCLE-02 | B6: Multi-Company & Isolation Regression | C6: Pengujian isolasi korporat kode, role matrix, permission | D6: 2026-10-03 | E6: 2026-10-04 | F6: 20 | G6: 20 | H6: 0 | I6: =G6/F6 | J6: Completed (Passed)
A7: CYCLE-03 | B7: ClosedXML & ARMS Data Interop | C7: Uji format Excel 21-kolom, import, export, formula proteksi | D7: 2026-10-05 | E7: 2026-10-06 | F7: 18 | G7: 18 | H7: 0 | I7: =G7/F7 | J7: Completed (Passed)
A8: CYCLE-04 | B8: Full E2E Regression Sprint 12 | C8: Pengujian regresi menyeluruh seluruh 19 modul aplikasi | D8: 2026-10-07 | E8: 2026-10-10 | F8: 75 | G8: 42 | H8: 1 | I8: =G8/F8 | J8: In Progress
A9: CYCLE-05 | B9: User Acceptance Testing (UAT) | C9: Pengujian skenario kerja nyata oleh perwakilan divisi operasional | D9: 2026-10-12 | E9: 2026-10-15 | F9: 30 | G9: 0 | H9: 0 | I9: =IF(F9>0, G9/F9, 0) | J9: Scheduled

Sheet Defect Log
A1: DEFECT LOG & BUG TRACKER - WORK TRACKER PRO v3.7
A4: Defect ID | B4: Ref TC ID | C4: Modul | D4: Ringkasan Masalah (Bug Summary) | E4: Severity | F4: Priority | G4: Status | H4: Dilaporkan Oleh | I4: Tgl Lapor | J4: Assigned Dev | K4: Solusi / Catatan Penyelesaian
A5: BUG-001 | B5: TC-KANB-002 | C5: Kanban Board | D5: Kartu kanban tidak auto-revert saat koneksi internet terputus di tengah drag-drop | E5: Major | F5: High | G5: In Progress | H5: QA Engineer B | I5: 2026-10-05 | J5: Frontend Lead | K5: Sedang menambahkan error callback di SortableJS agar trigger DOM rollback
A6: BUG-002 | B6: TC-NOTIF-003 | C6: Notifikasi & SMTP | D6: Tag variabel {{TaskTitle}} pada template email penugasan kadang ter-render kosong jika judul mengandung karakter khusus | E6: Moderate | F6: Medium | G6: Resolved | H6: QA Engineer D | I6: 2026-10-06 | J6: Backend Dev | K6: Diperbaiki dengan HtmlEncode sebelum replacement placeholder di EmailService.cs
